Workbook

Sheet Control_Panel
B2: 🤖 AI-POWERED ANALYTICS ENGINE — CONTROL PANEL
B3: Enterprise reporting | pandas analytics | AI-generated insights | Auto-updating dashboard
B5: 📋 WORKFLOW — HOW TO USE THIS SYSTEM | E5: 📊 LIVE SYSTEM STATUS
B6: STEP 1 | C6: 📂 Upload / paste your CSV into Raw_Data sheet (replace sample rows, keep or update headers) | E6: Raw Data Rows | F6: =COUNTA(Raw_Data!A:A)-1 -> 60
B7: STEP 2 | C7: ⚙️ Go to Mapping_Config → use yellow dropdowns in column B to map columns to system fields | E7: Raw Data Columns | F7: =COUNTA(Raw_Data!1:1) -> 8
B8: STEP 3 | C8: 🔧 Set Analysis Settings in Mapping_Config (threshold, GPT toggle, output path) | E8: Mapped Fields | F8: =COUNTIF(Mapping_Config!F5:F12,"✅ Mapped") -> 8
B9: STEP 4 | C9: ▶️ Run: python analytics_engine.py (from terminal or via .bat / shell script) | E9: Unmapped Required | F9: =COUNTIFS(Mapping_Config!F5:F8,"⚠️ Not Set") -> 0
B10: STEP 5 | C10: 📊 Results auto-populate in Summary sheet — KPIs, trends, AI insights, charts | E10: GPT Insights | F10: =Mapping_Config!B19 -> FALSE
E11: Email Enabled | F11: =Mapping_Config!B22 -> FALSE
E12: Analysis Status | F12: ⏳ Awaiting run...
B13: 📌 QUICK COMMANDS | E13: Last Updated | F13: —
B15: ▶ RUN ANALYSIS → python analytics_engine.py | C15: Cleans data, runs trends, generates insights, updates Summary sheet
B17: 📄 GENERATE REPORT → python analytics_engine.py --report | C17: Saves PDF + CSV summary to output/ folder
B19: 📧 EMAIL REPORT → python analytics_engine.py --email | C19: Sends formatted HTML email to recipients in Mapping_Config
B21: 🔁 SCHEDULE DAILY → python analytics_engine.py --schedule | C21: Sets up cron/Task Scheduler for automatic daily runs at 08:00
B23: 🔗 VBA MACRO — Assign to Excel button (Alt+F11 → Insert Module)
B24: Sub RunAnalysis()
B25: Shell "cmd /c cd /d C:\YourProject && python analytics_engine.py", vbHide
B26: End Sub
B28: Sub GenerateReport()
B29: Shell "cmd /c cd /d C:\YourProject && python analytics_engine.py --report", vbHide
B30: End Sub
B32: Mac: use AppleScript → do shell script "cd ~/YourProject && python3 analytics_engine.py"

Sheet Raw_Data
A1: Date | B1: Product | C1: Category | D1: Region | E1: Units_Sold | F1: Revenue | G1: Cost | H1: Customer_Segment
A2: 45292 | B2: Laptop | C2: Electronics | D2: North | E2: 10 | F2: 200 | G2: 90 | H2: Retail
A3: 45293 | B3: Sneakers | C3: Apparel | D3: South | E3: 17 | F3: 561 | G3: 258.06 | H3: Wholesale
A4: 45294 | B4: Garden Tools | C4: Home & Garden | D4: East | E4: 24 | F4: 1104 | G4: 518.88 | H4: Online
A5: 45295 | B5: Treadmill | C5: Sports | D5: West | E5: 31 | F5: 1829 | G5: 877.92 | H5: Retail
A6: 45296 | B6: Laptop | C6: Electronics | D6: North | E6: 38 | F6: 2736 | G6: 1340.64 | H6: Wholesale
A7: 45328 | B7: Sneakers | C7: Apparel | D7: South | E7: 45 | F7: 3825 | G7: 1912.5 | H7: Online
A8: 45329 | B8: Garden Tools | C8: Home & Garden | D8: East | E8: 52 | F8: 5096 | G8: 2598.96 | H8: Retail
A9: 45330 | B9: Treadmill | C9: Sports | D9: West | E9: 59 | F9: 6549 | G9: 3405.48 | H9: Wholesale
A10: 45331 | B10: Laptop | C10: Electronics | D10: North | E10: 66 | F10: 8184 | G10: 4337.52 | H10: Online
A11: 45332 | B11: Sneakers | C11: Apparel | D11: South | E11: 73 | F11: 10001 | G11: 5400.54 | H11: Retail
A12: 45362 | B12: Garden Tools | C12: Home & Garden | D12: East | E12: 80 | F12: 15600 | G12: 8580 | H12: Wholesale
A13: 45363 | B13: Treadmill | C13: Sports | D13: West | E13: 87 | F13: 18435.3 | G13: 10323.77 | H13: Online
... A61: 45630 | B61: Treadmill | C61: Sports | D61: West | E61: 63 | F61: 11781 | G61: 7539.84 | H61: Online

Sheet Mapping_Config
A1: ⚙️ COLUMN MAPPING CONFIGURATION — Map your dataset columns to system fields
A2: Step 1: Paste your CSV headers into the 'Available Columns' list (column H). Step 2: Select the correct column for each field using the yellow dropdowns (column B).
A4: System Field | B4: Mapped Column ▾ | C4: Required? | D4: Description | E4: Data Type | F4: Status | H4: Available CSV Columns (auto-detected from Raw_Data)
A5: Date / Transaction Date | B5: Date | C5: REQUIRED | D5: Date column (YYYY-MM-DD preferred) | E5: Date | F5: =IF(B5<>"","✅ Mapped","⚠️ Not Set") -> ✅ Mapped | H5: Date
A6: Revenue / Sales Amount | B6: Revenue | C6: REQUIRED | D6: Primary revenue/sales numeric column | E6: Number | F6: =IF(B6<>"","✅ Mapped","⚠️ Not Set") -> ✅ Mapped | H6: Product
A7: Product / Item Name | B7: Product | C7: REQUIRED | D7: Product or item name column | E7: Text | F7: =IF(B7<>"","✅ Mapped","⚠️ Not Set") -> ✅ Mapped | H7: Category
A8: Category / Department | B8: Category | C8: REQUIRED | D8: Category grouping column | E8: Text | F8: =IF(B8<>"","✅ Mapped","⚠️ Not Set") -> ✅ Mapped | H8: Region
A9: Region / Territory | B9: Region | C9: OPTIONAL | D9: Geographic region column | E9: Text | F9: =IF(B9<>"","✅ Mapped","⚠️ Not Set") -> ✅ Mapped | H9: Units_Sold
A10: Cost / COGS | B10: Cost | C10: OPTIONAL | D10: Cost of goods / expenses column | E10: Number | F10: =IF(B10<>"","✅ Mapped","⚠️ Not Set") -> ✅ Mapped | H10: Revenue
A11: Units / Quantity | B11: Units_Sold | C11: OPTIONAL | D11: Unit volume column | E11: Number | F11: =IF(B11<>"","✅ Mapped","⚠️ Not Set") -> ✅ Mapped | H11: Cost
A12: Customer Segment | B12: Customer_Segment | C12: OPTIONAL | D12: Customer type/tier column | E12: Text | F12: =IF(B12<>"","✅ Mapped","⚠️ Not Set") -> ✅ Mapped | H12: Customer_Segment
A15: 📊 ANALYSIS SETTINGS
A16: Trend Detection Window (months) | B16: 3 | C16: Months to compare for growth calculation
A17: Anomaly Threshold (%) | B17: 25 | C17: % change flagged as spike or drop
A18: Top N Categories | B18: 5 | C18: Number of top categories to surface
A19: Enable GPT Insights | B19: FALSE | C19: TRUE = call OpenAI API for narrative insights
A20: GPT API Key | B20: sk-... | C20: Paste OpenAI API key (kept local, never transmitted)
A21: Report Output Path | B21: output/ | C21: Relative folder for saving PDF/CSV reports
A22: Email Report On Completion | B22: FALSE | C22: TRUE = send email after each run
A23: Email Recipients | C23: Comma-separated: user1@co.com,user2@co.com

Sheet Summary
B1: 📊 AI ANALYTICS DASHBOARD | E1: Auto-generated by Analytics Engine | Powered by pandas + AI Insight Layer | I1: Last Run: —
B3: ⚡ KEY PERFORMANCE INDICATORS
B4: 💰 Total Revenue | D4: 📦 Total Units | F4: 📈 Avg Monthly Growth | H4: 🏆 Top Category | J4: 🌍 Top Region | L4: ⚠️ Anomalies Detected
B5: 0 | D5: 0 | F5: 0 | H5: — | J5: — | L5: 0
B6: YTD / All Time | D6: Across all products | F6: vs. Prior period | H6: By revenue | J6: By revenue | L6: Spikes / drops
B8: 🤖 AI-GENERATED BUSINESS INSIGHTS | J8: 🏆 TOP CATEGORIES / PRODUCTS
B9: 📈 TREND | C9: Run analysis to generate trend insight... | J9: Category | K9: Revenue | L9: Units | M9: Margin% | N9: Share% | O9: vs PY
B10: 🏆 TOP PERFORMER | C10: Run analysis to generate top performer insight... | J10: — | K10: 0 | L10: 0 | M10: 0 | N10: 0 | O10: 0
B11: ⚠️ ANOMALY | C11: Run analysis to generate anomaly insight... | J11: — | K11: 0 | L11: 0 | M11: 0 | N11: 0 | O11: 0
B12: 📉 RISK | C12: Run analysis to generate risk insight... | J12: — | K12: 0 | L12: 0 | M12: 0 | N12: 0 | O12: 0
B13: 💡 RECOMMENDATION | C13: Run analysis to generate AI recommendation... | J13: — | K13: 0 | L13: 0 | M13: 0 | N13: 0 | O13: 0
J14: — | K14: 0 | L14: 0 | M14: 0 | N14: 0 | O14: 0
B15: 📅 MONTHLY REVENUE TREND | J15: — | K15: 0 | L15: 0 | M15: 0 | N15: 0 | O15: 0
B16: Month | C16: Revenue | D16: Units | E16: Avg Order | F16: MoM Growth | G16: MoM Δ | H16: Trend
B17: — | C17: 0 | D17: 0 | E17: 0 | F17: 0 | G17: =0 -> 0 | H17: — | J17: 🌍 REGION PERFORMANCE
B18: — | C18: 0 | D18: 0 | E18: 0 | F18: 0 | G18: =C18-C17 -> 0 | H18: — | J18: Region | K18: Revenue | L18: Units | M18: Growth% | N18: Status | O18: Rank
B19: — | C19: 0 | D19: 0 | E19: 0 | F19: 0 | G19: =C19-C18 -> 0 | H19: — | J19: — | K19: 0 | L19: 0 | M19: 0 | N19: 0 | O19: 0
B20: — | C20: 0 | D20: 0 | E20: 0 | F20: 0 | G20: =C20-C19 -> 0 | H20: — | J20: — | K20: 0 | L20: 0 | M20: 0 | N20: 0 | O20: 0
B21: — | C21: 0 | D21: 0 | E21: 0 | F21: 0 | G21: =C21-C20 -> 0 | H21: — | J21: — | K21: 0 | L21: 0 | M21: 0 | N21: 0 | O21: 0
B22: — | C22: 0 | D22: 0 | E22: 0 | F22: 0 | G22: =C22-C21 -> 0 | H22: — | J22: — | K22: 0 | L22: 0 | M22: 0 | N22: 0 | O22: 0
B23: — | C23: 0 | D23: 0 | E23: 0 | F23: 0 | G23: =C23-C22 -> 0 | H23: — | J23: — | K23: 0 | L23: 0 | M23: 0 | N23: 0 | O23: 0
B24: — | C24: 0 | D24: 0 | E24: 0 | F24: 0 | G24: =C24-C23 -> 0 | H24: —
B25: — | C25: 0 | D25: 0 | E25: 0 | F25: 0 | G25: =C25-C24 -> 0 | H25: —
B26: — | C26: 0 | D26: 0 | E26: 0 | F26: 0 | G26: =C26-C25 -> 0 | H26: —
B27: — | C27: 0 | D27: 0 | E27: 0 | F27: 0 | G27: =C27-C26 -> 0 | H27: —
B28: — | C28: 0 | D28: 0 | E28: 0 | F28: 0 | G28: =C28-C27 -> 0 | H28: —
B30: ⚠️ ANOMALIES & ALERTS
B31: Date | C31: Metric | D31: Value | E31: Expected | F31: Deviation% | G31: Severity | H31: Description
B32: — | C32: — | D32: — | E32: — | F32: — | G32: — | H32: —
B33: — | C33: — | D33: — | E33: — | F33: — | G33: — | H33: —
B34: — | C34: — | D34: — | E34: — | F34: — | G34: — | H34: —
B35: — | C35: — | D35: — | E35: — | F35: — | G35: — | H35: —
B36: — | C36: — | D36: — | E36: — | F36: — | G36: — | H36: —
B37: — | C37: — | D37: — | E37: — | F37: — | G37: — | H37: —
B40: ⚙️ System: AI Analytics Engine v2.0 | Built with pandas, openpyxl, rule-based + GPT insights | Update Raw_Data → run python analytics_engine.py → dashboard refreshes

Sheet Python_Code
B1: 🐍 PYTHON ANALYTICS ENGINE — COMPLETE SETUP GUIDE
B2: analytics_engine.py | 7 modules | pandas + openpyxl + AI insights | v2.0
B4: 📦 STEP 1 — INSTALL DEPENDENCIES
B5: pip install pandas numpy openpyxl
B6: pip install openai # Only needed if using GPT insights
B8: # Verify installation:
B9: python -c "import pandas, openpyxl; print('✅ OK')"
B11: 📁 STEP 2 — FOLDER STRUCTURE
B12: YourProject/
B13: ├── analytics_engine.py ← Main Python script (see download instructions)
B14: ├── Book1.xlsx ← Your Excel workbook (rename EXCEL_FILE if needed)
B15: ├── run_windows.bat ← Windows double-click launcher
... B63: 📚 MODULE REFERENCE
B64: Module | C64: Description
B65: ExcelIO | C65: Reads Raw_Data + Mapping_Config; writes all results back to Summary sheet
B66: DataProcessor | C66: Cleans data: parses dates, numeric types, handles nulls, renames columns per mapping
B67: AnalyticsEngine | C67: KPIs, monthly trends, category/region breakdowns, Z-score anomaly detection
B68: InsightGenerator | C68: Rule-based + optional GPT insights — generates 5 business-focused narrative insights
B69: ReportGenerator | C69: Saves CSV tables + formatted TXT report to output/ folder with timestamps
B70: EmailSender | C70: HTML email via SMTP with KPI table + insights (credentials via env vars — never hardcode)
B71: Scheduler | C71: Windows Task Scheduler or Linux cron — daily automated runs via --schedule flag
B73: 📂 OUTPUT FILES (written to output/ folder)
B74: output/monthly_trend_YYYYMMDD_HHMM.csv | C74: Monthly revenue aggregation
B75: output/category_breakdown_YYYYMMDD_HHMM.csv | C75: Category performance table
B76: output/region_breakdown_YYYYMMDD_HHMM.csv | C76: Region performance table
B77: output/anomalies_YYYYMMDD_HHMM.csv | C77: Detected revenue spikes and drops
B78: output/insights_YYYYMMDD_HHMM.txt | C78: Human-readable business insights report
B79: output/analytics.log | C79: Full execution log with timestamps and error details
B81: 📧 EMAIL SETUP (environment variables — never put passwords in code)
B82: export SMTP_HOST=smtp.gmail.com # or your company SMTP server
B83: export SMTP_PORT=587
B84: export SMTP_USER=you@company.com
B85: export SMTP_PASS=your_app_password # Use Gmail App Password, not main password
B87: # On Windows, use System Environment Variables or PowerShell:
B88: $env:SMTP_USER = "you@company.com"
B89: $env:SMTP_PASS = "your_app_password"
B91: ⏰ DAILY SCHEDULER
B92: # Run once to configure — works on Windows and Mac/Linux:
B93: python analytics_engine.py --schedule
B95: # Windows: creates Task Scheduler task 'AI_Analytics_Daily' (runs at 08:00)
...
